<?xml version="1.0" ?>
<!-- =================================================================================== -->
<!-- |    This document was autogenerated by xacro from rover.xacro                    | -->
<!-- |    EDITING THIS FILE BY HAND IS NOT RECOMMENDED                                 | -->
<!-- =================================================================================== -->
<robot name="rover" xmlns:xacro="http://www.ros.org/wiki/xacro">
  <material name="black">
    <color rgba="0 0 0 1"/>
  </material>
  <material name="dark">
    <color rgba="0.2 0.2 0.2 1"/>
  </material>
  <material name="red">
    <color rgba="1.0 0.0 0.0 1.0"/>
  </material>
  <!-- <xacro:property name="base_width" value="0.14"/>
  <xacro:property name="base_length" value="0.37"/>
  <xacro:property name="base_height" value="0.0395"/>

  <xacro:property name="wheel_radius" value="${0.122/2}"/>
  <xacro:property name="wheel_width" value="0.06"/> -->
  <gazebo reference="base_link">
    <mu1> 20 </mu1>
    <mu2> 60 </mu2>
    <material> Gazebo/Black </material>
  </gazebo>
  <gazebo reference="wheelFrontRight">
    <mu1 value="20.0"/>
    <mu2 value="10.0"/>
    <kp value="100000.0"/>
    <kd value="1.0"/>
    <maxVel value="100.0"/>
    <minDepth value="0.0005"/>
    <material> Gazebo/DarkGrey </material>
  </gazebo>
  <gazebo reference="wheelFrontLeft">
    <mu1 value="20.0"/>
    <mu2 value="10.0"/>
    <kp value="100000.0"/>
    <kd value="1.0"/>
    <maxVel value="100.0"/>
    <minDepth value="0.0005"/>
    <material> Gazebo/DarkGrey </material>
  </gazebo>
  <gazebo reference="wheelRearRight">
    <mu1 value="20.0"/>
    <mu2 value="10.0"/>
    <kp value="100000.0"/>
    <kd value="1.0"/>
    <maxVel value="100.0"/>
    <minDepth value="0.0005"/>
    <material> Gazebo/DarkGrey </material>
  </gazebo>
  <gazebo reference="wheelRearLeft">
    <mu1 value="20.0"/>
    <mu2 value="10.0"/>
    <kp value="100000.0"/>
    <kd value="1.0"/>
    <maxVel value="100.0"/>
    <minDepth value="0.0005"/>
    <material> Gazebo/DarkGrey </material>
  </gazebo>
  <!-- camera -->
  <gazebo reference="front_camera">
    <material> Gazebo/Red </material>
    <sensor name="front_camera" type="camera">
      <update_rate>10.0</update_rate>
      <camera name="front_camera">
        <horizontal_fov>2.09</horizontal_fov>
        <image>
          <width>800</width>
          <height>600</height>
          <format>R8G8B8</format>
        </image>
        <clip>
          <near>0.02</near>
          <far>300</far>
        </clip>
        <noise>
          <type>gaussian</type>
          <mean>0.0</mean>
          <stddev>0.01</stddev>
        </noise>
      </camera>
      <plugin filename="libgazebo_ros_camera.so" name="camera_controller">
        <alwaysOn>true</alwaysOn>
        <updateRate>0.0</updateRate>
        <cameraName>chrzaszcz/front_camera</cameraName>
        <imageTopicName>image_raw</imageTopicName>
        <cameraInfoTopicName>camera_info</cameraInfoTopicName>
        <frameName>front_camera</frameName>
        <hackBaseline>0.07</hackBaseline>
        <distortionK1>0.0</distortionK1>
        <distortionK2>0.0</distortionK2>
        <distortionK3>0.0</distortionK3>
        <distortionT1>0.0</distortionT1>
        <distortionT2>0.0</distortionT2>
      </plugin>
    </sensor>
  </gazebo>
  <gazebo reference="camera2_link">
    <material> Gazebo/Red </material>
    <sensor name="camera2" type="camera">
      <update_rate>10.0</update_rate>
      <camera name="back">
        <horizontal_fov>2.09</horizontal_fov>
        <image>
          <width>1920</width>
          <height>1024</height>
          <format>R8G8B8</format>
        </image>
        <clip>
          <near>0.02</near>
          <far>300</far>
        </clip>
        <noise>
          <type>gaussian</type>
          <mean>0.0</mean>
          <stddev>0.01</stddev>
        </noise>
      </camera>
      <plugin filename="libgazebo_ros_camera.so" name="camera_controller">
        <alwaysOn>true</alwaysOn>
        <updateRate>0.0</updateRate>
        <cameraName>chrzaszcz/camera2</cameraName>
        <imageTopicName>image_raw</imageTopicName>
        <cameraInfoTopicName>camera_info</cameraInfoTopicName>
        <frameName>camera2_link</frameName>
        <hackBaseline>0.07</hackBaseline>
        <distortionK1>0.0</distortionK1>
        <distortionK2>0.0</distortionK2>
        <distortionK3>0.0</distortionK3>
        <distortionT1>0.0</distortionT1>
        <distortionT2>0.0</distortionT2>
      </plugin>
    </sensor>
  </gazebo>
  <gazebo>
    <plugin filename="libgazebo_ros_skid_steer_drive.so" name="skid_steer_drive_controller">
      <updateRate>100.0</updateRate>
      <robotNamespace>/chrzaszcz</robotNamespace>
      <leftFrontJoint>baseToWheelFrontLeft</leftFrontJoint>
      <rightFrontJoint>baseToWheelFrontRight</rightFrontJoint>
      <leftRearJoint>baseToWheelRearLeft</leftRearJoint>
      <rightRearJoint>baseToWheelRearRight</rightRearJoint>
      <wheelSeparation>0.14</wheelSeparation>
      <wheelDiameter>0.122</wheelDiameter>
      <robotBaseFrame>base_link</robotBaseFrame>
      <torque>100</torque>
      <topicName>cmd_vel</topicName>
      <broadcastTF>true</broadcastTF>
    </plugin>
  </gazebo>
  <link name="base_link">
     --&gt;
    
    <visual>
      <geometry>
        <box size="0.14 0.37 0.0395"/>
      </geometry>
      <material name="black"/>
    </visual>
    <collision>
      <geometry>
        <box size="0.14 0.37 0.0395"/>
      </geometry>
    </collision>
    <inertial>
      <mass value="0.9"/>
      <inertia ixx="0.01038451875" ixy="0.0" ixz="0.0" iyy="0.00158701875" iyz="0.0" izz="0.0117375"/>
      <origin rpy="0 0 0" xyz="0 0 0"/>
    </inertial>
  </link>
  <link name="wheelFrontRight">
    <visual>
      <geometry>
        <cylinder length="0.06" radius="0.061"/>
      </geometry>
      <origin rpy="0 1.5708 0" xyz="0 0 0 "/>
      <material name="dark"/>
    </visual>
    <collision>
      <geometry>
        <cylinder length="0.06" radius="0.061"/>
      </geometry>
      <origin rpy="0 1.5708 0" xyz="0 0 0"/>
    </collision>
    <inertial>
      <mass value="0.25"/>
      <inertia ixx="0.0003075625" ixy="0.0" ixz="0.0" iyy="0.0003075625" iyz="0.0" izz="0.000465125"/>
      <origin rpy="0 1.5708 0" xyz="0 0 0"/>
    </inertial>
  </link>
  <joint name="baseToWheelFrontRight" type="continuous">
    <parent link="base_link"/>
    <child link="wheelFrontRight"/>
    <origin rpy="0 0 3.1416" xyz="0.1 0.148 0"/>
    <dynamics damping="0.00005" friction="0.0001"/>
  </joint>
  <link name="wheelFrontLeft">
    <visual>
      <geometry>
        <cylinder length="0.06" radius="0.061"/>
      </geometry>
      <origin rpy="0 1.5708 0" xyz="0 0 0 "/>
      <material name="dark"/>
    </visual>
    <collision>
      <geometry>
        <cylinder length="0.06" radius="0.061"/>
      </geometry>
      <origin rpy="0 1.5708 0" xyz="0 0 0"/>
    </collision>
    <inertial>
      <mass value="0.25"/>
      <inertia ixx="0.0003075625" ixy="0.0" ixz="0.0" iyy="0.0003075625" iyz="0.0" izz="0.000465125"/>
      <origin rpy="0 1.5708 0" xyz="0 0 0"/>
    </inertial>
  </link>
  <joint name="baseToWheelFrontLeft" type="continuous">
    <parent link="base_link"/>
    <child link="wheelFrontLeft"/>
    <origin rpy="0 0 3.1416" xyz="-0.1 0.148 0"/>
    <dynamics damping="0.00005" friction="0.0001"/>
  </joint>
  <link name="wheelRearRight">
    <visual>
      <geometry>
        <cylinder length="0.06" radius="0.061"/>
      </geometry>
      <origin rpy="0 1.5708 0" xyz="0 0 0 "/>
      <material name="dark"/>
    </visual>
    <collision>
      <geometry>
        <cylinder length="0.06" radius="0.061"/>
      </geometry>
      <origin rpy="0 1.5708 0" xyz="0 0 0"/>
    </collision>
    <inertial>
      <mass value="0.25"/>
      <inertia ixx="0.0003075625" ixy="0.0" ixz="0.0" iyy="0.0003075625" iyz="0.0" izz="0.000465125"/>
      <origin rpy="0 1.5708 0" xyz="0 0 0"/>
    </inertial>
  </link>
  <joint name="baseToWheelRearRight" type="continuous">
    <parent link="base_link"/>
    <child link="wheelRearRight"/>
    <origin rpy="0 0 3.1416" xyz="0.1 -0.148 0"/>
    <dynamics damping="0.00005" friction="0.0001"/>
  </joint>
  <link name="wheelRearLeft">
    <visual>
      <geometry>
        <cylinder length="0.06" radius="0.061"/>
      </geometry>
      <origin rpy="0 1.5708 0" xyz="0 0 0 "/>
      <material name="dark"/>
    </visual>
    <collision>
      <geometry>
        <cylinder length="0.06" radius="0.061"/>
      </geometry>
      <origin rpy="0 1.5708 0" xyz="0 0 0"/>
    </collision>
    <inertial>
      <mass value="0.25"/>
      <inertia ixx="0.0003075625" ixy="0.0" ixz="0.0" iyy="0.0003075625" iyz="0.0" izz="0.000465125"/>
      <origin rpy="0 1.5708 0" xyz="0 0 0"/>
    </inertial>
  </link>
  <joint name="baseToWheelRearLeft" type="continuous">
    <parent link="base_link"/>
    <child link="wheelRearLeft"/>
    <origin rpy="0 0 3.1416" xyz="-0.1 -0.148 0"/>
    <dynamics damping="0.00005" friction="0.0001"/>
  </joint>
  <link name="front_camera">
    <collision>
      <origin rpy="0 0 0" xyz="0 0 0"/>
      <geometry>
        <box size="0.02 0.02 0.02"/>
      </geometry>
    </collision>
    <visual>
      <origin rpy="0 0 0" xyz="0 0 0"/>
      <geometry>
        <box size="0.02 0.04 0.04"/>
      </geometry>
      <material name="red"/>
    </visual>
    <inertial>
      <mass value="1e-5"/>
      <origin rpy="0 0 0" xyz="0 0 0"/>
      <inertia ixx="1e-6" ixy="0" ixz="0" iyy="1e-6" iyz="0" izz="1e-6"/>
    </inertial>
  </link>
  <joint name="front_camera_joint" type="fixed">
    <axis xyz="0 1 0"/>
    <origin rpy="3.1416 0 1.5708" xyz="0 0.195 0.01975"/>
    <parent link="base_link"/>
    <child link="front_camera"/>
  </joint>
  <link name="camera2_link">
    <collision>
      <origin rpy="0 0 0" xyz="0 0 0"/>
      <geometry>
        <box size="0.02 0.02 0.02"/>
      </geometry>
    </collision>
    <visual>
      <origin rpy="0 0 0" xyz="0 0 0"/>
      <geometry>
        <box size="0.02 0.02 0.02"/>
      </geometry>
      <material name="red"/>
    </visual>
    <inertial>
      <mass value="1e-5"/>
      <origin rpy="0 0 0" xyz="0 0 0"/>
      <inertia ixx="1e-6" ixy="0" ixz="0" iyy="1e-6" iyz="0" izz="1e-6"/>
    </inertial>
  </link>
  <joint name="camera2_joint" type="fixed">
    <origin rpy="0 0 1.5708" xyz="0 -0.1665 0.158"/>
    <parent link="base_link"/>
    <child link="camera2_link"/>
  </joint>
  <link name="camera2_rod">
    <collision>
      <origin rpy="0 0 0" xyz="0 0 0"/>
      <geometry>
        <box size="0.005 0.005 0.158"/>
      </geometry>
    </collision>
    <visual>
      <origin rpy="0 0 0" xyz="0 0 0"/>
      <geometry>
        <box size="0.01 0.01 0.158"/>
      </geometry>
      <material name="dark"/>
    </visual>
    <inertial>
      <mass value="1e-5"/>
      <origin rpy="0 0 0" xyz="0 0 0"/>
      <inertia ixx="1e-6" ixy="0" ixz="0" iyy="1e-6" iyz="0" izz="1e-6"/>
    </inertial>
  </link>
  <joint name="camera2_rod_joint" type="fixed">
    <origin rpy="0 0 1.5708" xyz="0 -0.1665 0.079"/>
    <parent link="base_link"/>
    <child link="camera2_rod"/>
  </joint>
  <!-- <material name="dark">
    <color rgba="0.2 0.2 0.2 1"/>
  </material> -->
  <material name="light">
    <color rgba="0.7 0.7 0.7 1"/>
  </material>
  <gazebo>
    <plugin filename="libgazebo_ros_control.so" name="gazebo_ros_control">
      <robotNamespace>/chrzaszcz</robotNamespace>
      <robotSimType>gazebo_ros_control/DefaultRobotHWSim</robotSimType>
    </plugin>
  </gazebo>
  <gazebo reference="left_gripper">
    <mu1> 10000 </mu1>
    <mu2> 10000 </mu2>
    <material> Gazebo/Grey </material>
  </gazebo>
  <gazebo reference="right_gripper">
    <mu1> 10000 </mu1>
    <mu2> 10000 </mu2>
    <material> Gazebo/Grey </material>
  </gazebo>
  <gazebo reference="arm_base">
    <mu2> 20 </mu2>
    <mu1> 30 </mu1>
    <material> Gazebo/DarkGrey </material>
  </gazebo>
  <gazebo reference="first_link">
    <mu2> 20 </mu2>
    <mu1> 30 </mu1>
    <material> Gazebo/DarkGrey </material>
  </gazebo>
  <gazebo reference="second_link">
    <mu2> 20 </mu2>
    <mu1> 30 </mu1>
    <material> Gazebo/Grey </material>
  </gazebo>
  <gazebo reference="third_link">
    <mu2> 20 </mu2>
    <mu1> 30 </mu1>
    <material> Gazebo/DarkGrey </material>
  </gazebo>
  <gazebo reference="fourth_link">
    <mu2> 20 </mu2>
    <mu1> 30 </mu1>
    <material> Gazebo/DarkGrey </material>
  </gazebo>
  <gazebo reference="fifth_link">
    <mu2> 20 </mu2>
    <mu1> 30 </mu1>
    <material> Gazebo/Grey </material>
  </gazebo>
  <gazebo>
    <plugin filename="libgazebo_grasp_fix.so" name="gazebo_grasp_fix">
      <arm>
        <arm_name>dagu_arm</arm_name>
        <palm_link> fifth_link  </palm_link>
        <gripper_link> left_gripper </gripper_link>
        <gripper_link> right_gripper </gripper_link>
      </arm>
      <forces_angle_tolerance>100</forces_angle_tolerance>
      <update_rate>4</update_rate>
      <grip_count_threshold>4</grip_count_threshold>
      <max_grip_count>8</max_grip_count>
      <release_tolerance>0.005</release_tolerance>
      <disable_collisions_on_attach>false</disable_collisions_on_attach>
      <contact_topic>__default_topic__</contact_topic>
    </plugin>
  </gazebo>
  <gazebo reference="arm_camera">
    <material> Gazebo/Red </material>
    <sensor name="arm_camera" type="camera">
      <update_rate>10.0</update_rate>
      <camera name="arm">
        <horizontal_fov>1.045</horizontal_fov>
        <image>
          <width>1920</width>
          <height>1024</height>
          <format>R8G8B8</format>
        </image>
        <clip>
          <near>0.02</near>
          <far>300</far>
        </clip>
        <noise>
          <type>gaussian</type>
          <mean>0.0</mean>
          <stddev>0.01</stddev>
        </noise>
      </camera>
      <plugin filename="libgazebo_ros_camera.so" name="camera_controller">
        <alwaysOn>true</alwaysOn>
        <updateRate>0.0</updateRate>
        <cameraName>chrzaszcz/arm_camera</cameraName>
        <imageTopicName>image_raw</imageTopicName>
        <cameraInfoTopicName>camera_info</cameraInfoTopicName>
        <frameName>arm_camera</frameName>
        <hackBaseline>0.07</hackBaseline>
        <distortionK1>0.0</distortionK1>
        <distortionK2>0.0</distortionK2>
        <distortionK3>0.0</distortionK3>
        <distortionT1>0.0</distortionT1>
        <distortionT2>0.0</distortionT2>
      </plugin>
    </sensor>
  </gazebo>
  <link name="arm_base">
    <visual>
      <geometry>
        <box size="0.055 0.02 0.051"/>
      </geometry>
      <origin xyz="0 0 0.0255"/>
      <material name="dark"/>
    </visual>
    <collision>
      <geometry>
        <box size="0.055 0.02 0.051"/>
      </geometry>
      <origin xyz="0 0 0.0255"/>
    </collision>
    <inertial>
      <mass value="0.1"/>
      <inertia ixx="4.68833333333e-05" ixy="0.0" ixz="0.0" iyy="2.85416666667e-05" iyz="0.0" izz="2.50083333333e-05"/>
    </inertial>
  </link>
  <link name="first_link">
    <visual>
      <geometry>
        <box size="0.06 0.038 0.035"/>
      </geometry>
      <origin xyz="-0.013 0 0"/>
      <material name="dark"/>
    </visual>
    <collision>
      <geometry>
        <box size="0.06 0.038 0.035"/>
      </geometry>
      <origin xyz="-0.013 0 0"/>
    </collision>
    <inertial>
      <mass value="0.1"/>
      <inertia ixx="4.02083333333e-05" ixy="0.0" ixz="0.0" iyy="4.20333333333e-05" iyz="0.0" izz="2.22416666667e-05"/>
    </inertial>
  </link>
  <joint name="first_to_base" type="revolute">
    <parent link="arm_base"/>
    <child link="first_link"/>
    <axis xyz="0 0 1"/>
    <origin xyz="0.0105 0 0.0685"/>
    <limit effort="1000.0" lower="-1.57079632679" upper="1.57079632679" velocity="0.175"/>
  </joint>
  <transmission name="transmission_first_to_base">
    <type>transmission_interface/SimpleTransmission</type>
    <joint name="first_to_base">
      <hardwareInterface>hardware_interface/EffortJointInterface</hardwareInterface>
    </joint>
    <actuator name="motor1">
      <hardwareInterface>hardware_interface/EffortJointInterface</hardwareInterface>
      <mechanicalReduction>1</mechanicalReduction>
    </actuator>
  </transmission>
  <link name="second_link">
    <visual>
      <geometry>
        <box size="0.106 0.06 0.026"/>
      </geometry>
      <origin xyz="0.04 0 0"/>
      <material name="light"/>
    </visual>
    <collision>
      <geometry>
        <box size="0.106 0.06 0.026"/>
      </geometry>
      <origin xyz="0.04 0 0"/>
    </collision>
    <inertial>
      <mass value="0.1"/>
      <inertia ixx="9.92666666667e-05" ixy="0.0" ixz="0.0" iyy="0.000123633333333" iyz="0.0" izz="3.56333333333e-05"/>
    </inertial>
  </link>
  <joint name="second_to_first" type="revolute">
    <parent link="first_link"/>
    <child link="second_link"/>
    <axis xyz="0 1 0"/>
    <origin rpy="0 -1.57079632679 0" xyz="0 0 0"/>
    <limit effort="1000.0" lower="-1.57079632679" upper="1.57079632679" velocity="0.175"/>
  </joint>
  <transmission name="transmission_second_to_first">
    <type>transmission_interface/SimpleTransmission</type>
    <joint name="second_to_first">
      <hardwareInterface>hardware_interface/EffortJointInterface</hardwareInterface>
    </joint>
    <actuator name="motor2">
      <hardwareInterface>hardware_interface/EffortJointInterface</hardwareInterface>
      <mechanicalReduction>1</mechanicalReduction>
    </actuator>
  </transmission>
  <link name="third_link">
    <visual>
      <geometry>
        <box size="0.12 0.038 0.03"/>
      </geometry>
      <origin xyz="0.04 0 0"/>
      <material name="dark"/>
    </visual>
    <collision>
      <geometry>
        <box size="0.12 0.038 0.03"/>
      </geometry>
      <origin xyz="0.04 0 0"/>
    </collision>
    <inertial>
      <mass value="0.1"/>
      <inertia ixx="0.0001275" ixy="0.0" ixz="0.0" iyy="0.000132033333333" iyz="0.0" izz="1.95333333333e-05"/>
    </inertial>
  </link>
  <joint name="third_to_second" type="revolute">
    <parent link="second_link"/>
    <child link="third_link"/>
    <axis xyz="0 1 0"/>
    <origin rpy="0 0 0" xyz="0.08 0 0"/>
    <limit effort="1000.0" lower="-1.57079632679" upper="1.57079632679" velocity="0.175"/>
  </joint>
  <transmission name="transmission_third_to_second">
    <type>transmission_interface/SimpleTransmission</type>
    <joint name="third_to_second">
      <hardwareInterface>hardware_interface/EffortJointInterface</hardwareInterface>
    </joint>
    <actuator name="motor3">
      <hardwareInterface>hardware_interface/EffortJointInterface</hardwareInterface>
      <mechanicalReduction>1</mechanicalReduction>
    </actuator>
  </transmission>
  <link name="fourth_link">
    <visual>
      <geometry>
        <box size="0.073 0.06 0.024"/>
      </geometry>
      <origin xyz="0.024 0 0"/>
      <material name="dark"/>
    </visual>
    <collision>
      <geometry>
        <box size="0.073 0.06 0.024"/>
      </geometry>
      <origin xyz="0.024 0 0"/>
    </collision>
    <inertial>
      <mass value="0.1"/>
      <inertia ixx="4.92083333333e-05" ixy="0.0" ixz="0.0" iyy="7.44083333333e-05" iyz="0.0" izz="3.48e-05"/>
    </inertial>
  </link>
  <joint name="fourth_to_third" type="revolute">
    <parent link="third_link"/>
    <child link="fourth_link"/>
    <axis xyz="0 1 0"/>
    <origin rpy="0 0 0" xyz="0.08 0 0"/>
    <limit effort="1000.0" lower="-1.57079632679" upper="1.57079632679" velocity="0.175"/>
  </joint>
  <transmission name="transmission_fourth_to_third">
    <type>transmission_interface/SimpleTransmission</type>
    <joint name="fourth_to_third">
      <hardwareInterface>hardware_interface/EffortJointInterface</hardwareInterface>
    </joint>
    <actuator name="motor4">
      <hardwareInterface>hardware_interface/EffortJointInterface</hardwareInterface>
      <mechanicalReduction>1</mechanicalReduction>
    </actuator>
  </transmission>
  <link name="fifth_link">
    <visual>
      <geometry>
        <box size="0.073 0.036 0.01"/>
      </geometry>
      <origin xyz="0.0 0 0"/>
      <material name="light"/>
    </visual>
    <collision>
      <geometry>
        <box size="0.073 0.036 0.01"/>
      </geometry>
      <origin xyz="0.0 0 0"/>
    </collision>
    <inertial>
      <mass value="0.1"/>
      <inertia ixx="4.52416666667e-05" ixy="0.0" ixz="0.0" iyy="5.52083333333e-05" iyz="0.0" izz="1.16333333333e-05"/>
    </inertial>
  </link>
  <joint name="fifth_to_fourth" type="revolute">
    <parent link="fourth_link"/>
    <child link="fifth_link"/>
    <axis xyz="1 0 0"/>
    <origin rpy="0 0 0" xyz="0.097 -0.01 0"/>
    <limit effort="1000.0" lower="-3.14159265359" upper="0" velocity="0.175"/>
  </joint>
  <transmission name="transmission_fifth_to_fourth">
    <type>transmission_interface/SimpleTransmission</type>
    <joint name="fifth_to_fourth">
      <hardwareInterface>hardware_interface/EffortJointInterface</hardwareInterface>
    </joint>
    <actuator name="motor5">
      <hardwareInterface>hardware_interface/EffortJointInterface</hardwareInterface>
      <mechanicalReduction>1</mechanicalReduction>
    </actuator>
  </transmission>
  <link name="right_gripper">
    <visual>
      <geometry>
        <box size="0.05 0.011 0.007"/>
      </geometry>
      <origin xyz="0.025 0.0055 0"/>
      <material name="light"/>
    </visual>
    <collision>
      <geometry>
        <box size="0.05 0.011 0.007"/>
      </geometry>
      <origin xyz="0.025 0.0055 0"/>
      <material name="light"/>
    </collision>
    <inertial>
      <mass value="0.01"/>
      <inertia ixx="2.12416666667e-06" ixy="0.0" ixz="0.0" iyy="2.18416666667e-06" iyz="0.0" izz="1.41666666667e-07"/>
    </inertial>
  </link>
  <joint name="right_gripper_to_fifth_link" type="prismatic">
    <parent link="fifth_link"/>
    <child link="right_gripper"/>
    <axis xyz="0 1 0"/>
    <origin rpy="0 0 0" xyz="0.0365 0 0"/>
    <limit effort="1000.0" lower="0" upper="0.035" velocity="0.01"/>
  </joint>
  <transmission name="transmission_right_gripper_to_fifth_link">
    <type>transmission_interface/SimpleTransmission</type>
    <joint name="right_gripper_to_fifth_link">
      <hardwareInterface>hardware_interface/EffortJointInterface</hardwareInterface>
    </joint>
    <actuator name="motor6">
      <hardwareInterface>hardware_interface/EffortJointInterface</hardwareInterface>
      <mechanicalReduction>1</mechanicalReduction>
    </actuator>
  </transmission>
  <link name="left_gripper">
    <visual>
      <geometry>
        <box size="0.05 0.011 0.007"/>
      </geometry>
      <origin xyz="0.025 -0.0055 0"/>
      <material name="light"/>
    </visual>
    <collision>
      <geometry>
        <box size="0.05 0.011 0.007"/>
      </geometry>
      <origin xyz="0.025 -0.0055 0"/>
      <material name="light"/>
    </collision>
    <inertial>
      <mass value="0.01"/>
      <inertia ixx="2.12416666667e-06" ixy="0.0" ixz="0.0" iyy="2.18416666667e-06" iyz="0.0" izz="1.41666666667e-07"/>
    </inertial>
  </link>
  <joint name="left_gripper_to_fifth_link" type="prismatic">
    <parent link="fifth_link"/>
    <child link="left_gripper"/>
    <axis xyz="0 1 0"/>
    <origin rpy="0 0 0" xyz="0.0365 0 0"/>
    <limit effort="1000.0" lower="-0.035" upper="0.0" velocity="0.01"/>
    <mimic joint="right_gripper_to_fifth_link" multiplier="-1"/>
  </joint>
  <transmission name="transmission_left_gripper_to_fifth_link">
    <type>transmission_interface/SimpleTransmission</type>
    <joint name="left_gripper_to_fifth_link">
      <hardwareInterface>hardware_interface/EffortJointInterface</hardwareInterface>
    </joint>
    <actuator name="motor7">
      <hardwareInterface>hardware_interface/EffortJointInterface</hardwareInterface>
      <mechanicalReduction>-1</mechanicalReduction>
    </actuator>
  </transmission>
  <link name="arm_camera">
    <collision>
      <origin rpy="0 0 0" xyz="0 0 0"/>
      <geometry>
        <box size="0.02 0.04 0.02"/>
      </geometry>
    </collision>
    <visual>
      <origin rpy="0 0 0" xyz="0 0 0"/>
      <geometry>
        <box size="0.02 0.04 0.02"/>
      </geometry>
      <material name="red"/>
    </visual>
    <inertial>
      <mass value="1e-5"/>
      <origin rpy="0 0 0" xyz="0 0 0"/>
      <inertia ixx="1e-6" ixy="0" ixz="0" iyy="1e-6" iyz="0" izz="1e-6"/>
    </inertial>
  </link>
  <joint name="arm_camera_joint" type="fixed">
    <axis xyz="0 1 0"/>
    <origin rpy="0 0 0" xyz="0 0 0.015"/>
    <parent link="fifth_link"/>
    <child link="arm_camera"/>
  </joint>
  <joint name="robotArm_to_fourWheelBase" type="fixed">
    <parent link="base_link"/>
    <child link="arm_base"/>
    <origin rpy="0 0 1.57079632679" xyz="-0.042 0.148 0"/>
  </joint>
</robot>

